[2024-05-26 02:51:18.836] RUN   (webs.run) :: Starting workflow (name=moldesign)
[2024-05-26 02:51:18.836] RUN   (webs.run) :: name='moldesign' timestamp=datetime.datetime(2024, 5, 26, 2, 51, 18, 835782) executor=ProcessPoolConfig(max_processes=32) transformer=NullTransformerConfig() filter=FilterConfig(filter_type=None, filter_min_size=0, filter_max_size=inf) run=RunConfig(log_file_level='INFO', log_file_name='log.txt', log_level='INFO', task_record_file_name='tasks.json', run_dir_format='/home/cc/escience24-taps-analysis/runs/makespan/{name}/process-pool/{timestamp}') workflow=MoldesignWorkflowConfig(dataset='/home/cc/taps/data/QM9-search.tsv', initial_count=16, search_count=64, batch_size=16, seed=0)
[2024-05-26 02:51:18.836] RUN   (webs.run) :: Runtime directory: /home/cc/escience24-taps-analysis/runs/makespan/moldesign/process-pool/2024-05-26-02-51-18
[2024-05-26 02:51:18.975] WORK  (webs.wf.moldesign.workflow) :: Loaded search space (size=130,258)
[2024-05-26 02:51:19.073] WORK  (webs.wf.moldesign.workflow) :: Submitted initial computations
[2024-05-26 02:51:19.074] INFO  (webs.wf.moldesign.workflow) :: Initial set: ['NC(=O)C12CN1C(=O)C2', 'CC12CCC(C1)C(=O)C2', 'CNC1=NC=NOC1=O', 'C1OC11CCCC1', 'COC12CCC1(O)C2O', 'OC1C=CC=CC=C1', 'CCC(C)C1COCO1', 'COC1=CC(C)=C(N)N1', 'CNC1=C(NC=N1)C=O', 'OCC1CC1OCC#C', 'OC1C=C2CN3C1C23', 'OC1CCC23CC12CO3', 'CCC1=COC=C1OC', 'CC1CCCCC(=O)C1', 'CC12OC3C4C(C14)C23', 'CC1OC2C3C1CC23O']
[2024-05-26 02:51:19.179] ERROR (concurrent.futures) :: exception calling callback for <Future at 0x7f2184cce150 state=finished raised ValueError>
concurrent.futures.process._RemoteTraceback: 
"""
Traceback (most recent call last):
  File "/home/cc/miniconda3/envs/taps/lib/python3.11/concurrent/futures/process.py", line 261, in _process_worker
    r = call_item.fn(*call_item.args, **call_item.kwargs)
        ^^^^^^^^^^^^^^^^^^^^^^^^^^^^^^^^^^^^^^^^^^^^^^^^^
  File "/home/cc/taps/webs/executor/workflow.py", line 118, in __call__
    result = self.function(*args, **kwargs)
             ^^^^^^^^^^^^^^^^^^^^^^^^^^^^^^
  File "/home/cc/taps/webs/wf/moldesign/chemfunctions.py", line 118, in _compute_vertical
    xyz = generate_initial_xyz(smiles)
          ^^^^^^^^^^^^^^^^^^^^^^^^^^^^
  File "/home/cc/taps/webs/wf/moldesign/chemfunctions.py", line 72, in generate_initial_xyz
    AllChem.MMFFOptimizeMolecule(mol)
ValueError: Bad Conformer Id
"""

The above exception was the direct cause of the following exception:

Traceback (most recent call last):
  File "/home/cc/miniconda3/envs/taps/lib/python3.11/concurrent/futures/_base.py", line 340, in _invoke_callbacks
    callback(self)
  File "/home/cc/taps/webs/executor/workflow.py", line 271, in _task_done_callback
    execution_info = future.result().info
                     ^^^^^^^^^^^^^^^
  File "/home/cc/miniconda3/envs/taps/lib/python3.11/concurrent/futures/_base.py", line 449, in result
    return self.__get_result()
           ^^^^^^^^^^^^^^^^^^^
  File "/home/cc/miniconda3/envs/taps/lib/python3.11/concurrent/futures/_base.py", line 401, in __get_result
    raise self._exception
ValueError: Bad Conformer Id
[2024-05-26 02:51:19.278] ERROR (concurrent.futures) :: exception calling callback for <Future at 0x7f2184ccd310 state=finished raised ValueError>
concurrent.futures.process._RemoteTraceback: 
"""
Traceback (most recent call last):
  File "/home/cc/miniconda3/envs/taps/lib/python3.11/concurrent/futures/process.py", line 261, in _process_worker
    r = call_item.fn(*call_item.args, **call_item.kwargs)
        ^^^^^^^^^^^^^^^^^^^^^^^^^^^^^^^^^^^^^^^^^^^^^^^^^
  File "/home/cc/taps/webs/executor/workflow.py", line 118, in __call__
    result = self.function(*args, **kwargs)
             ^^^^^^^^^^^^^^^^^^^^^^^^^^^^^^
  File "/home/cc/taps/webs/wf/moldesign/chemfunctions.py", line 118, in _compute_vertical
    xyz = generate_initial_xyz(smiles)
          ^^^^^^^^^^^^^^^^^^^^^^^^^^^^
  File "/home/cc/taps/webs/wf/moldesign/chemfunctions.py", line 72, in generate_initial_xyz
    AllChem.MMFFOptimizeMolecule(mol)
ValueError: Bad Conformer Id
"""

The above exception was the direct cause of the following exception:

Traceback (most recent call last):
  File "/home/cc/miniconda3/envs/taps/lib/python3.11/concurrent/futures/_base.py", line 340, in _invoke_callbacks
    callback(self)
  File "/home/cc/taps/webs/executor/workflow.py", line 271, in _task_done_callback
    execution_info = future.result().info
                     ^^^^^^^^^^^^^^^
  File "/home/cc/miniconda3/envs/taps/lib/python3.11/concurrent/futures/_base.py", line 449, in result
    return self.__get_result()
           ^^^^^^^^^^^^^^^^^^^
  File "/home/cc/miniconda3/envs/taps/lib/python3.11/concurrent/futures/_base.py", line 401, in __get_result
    raise self._exception
ValueError: Bad Conformer Id
[2024-05-26 02:51:20.634] WORK  (webs.wf.moldesign.workflow) :: Done computing initial set
[2024-05-26 02:51:20.636] WORK  (webs.wf.moldesign.workflow) :: Created initial training set (size=16)
[2024-05-26 02:51:20.637] WORK  (webs.wf.moldesign.workflow) :: Submitting inference tasks
[2024-05-26 02:51:37.924] WORK  (webs.wf.moldesign.workflow) :: Inference results received (size=130258)
[2024-05-26 02:51:37.957] WORK  (webs.wf.moldesign.workflow) :: Submitted new computations (size=16)
[2024-05-26 02:51:38.034] ERROR (concurrent.futures) :: exception calling callback for <Future at 0x7f2187c40b50 state=finished raised ValueError>
concurrent.futures.process._RemoteTraceback: 
"""
Traceback (most recent call last):
  File "/home/cc/miniconda3/envs/taps/lib/python3.11/concurrent/futures/process.py", line 261, in _process_worker
    r = call_item.fn(*call_item.args, **call_item.kwargs)
        ^^^^^^^^^^^^^^^^^^^^^^^^^^^^^^^^^^^^^^^^^^^^^^^^^
  File "/home/cc/taps/webs/executor/workflow.py", line 118, in __call__
    result = self.function(*args, **kwargs)
             ^^^^^^^^^^^^^^^^^^^^^^^^^^^^^^
  File "/home/cc/taps/webs/wf/moldesign/chemfunctions.py", line 118, in _compute_vertical
    xyz = generate_initial_xyz(smiles)
          ^^^^^^^^^^^^^^^^^^^^^^^^^^^^
  File "/home/cc/taps/webs/wf/moldesign/chemfunctions.py", line 72, in generate_initial_xyz
    AllChem.MMFFOptimizeMolecule(mol)
ValueError: Bad Conformer Id
"""

The above exception was the direct cause of the following exception:

Traceback (most recent call last):
  File "/home/cc/miniconda3/envs/taps/lib/python3.11/concurrent/futures/_base.py", line 340, in _invoke_callbacks
    callback(self)
  File "/home/cc/taps/webs/executor/workflow.py", line 271, in _task_done_callback
    execution_info = future.result().info
                     ^^^^^^^^^^^^^^^
  File "/home/cc/miniconda3/envs/taps/lib/python3.11/concurrent/futures/_base.py", line 449, in result
    return self.__get_result()
           ^^^^^^^^^^^^^^^^^^^
  File "/home/cc/miniconda3/envs/taps/lib/python3.11/concurrent/futures/_base.py", line 401, in __get_result
    raise self._exception
ValueError: Bad Conformer Id
[2024-05-26 02:51:39.658] WORK  (webs.wf.moldesign.workflow) :: Submitting inference tasks
[2024-05-26 02:51:58.469] WORK  (webs.wf.moldesign.workflow) :: Inference results received (size=130258)
[2024-05-26 02:51:58.506] WORK  (webs.wf.moldesign.workflow) :: Submitted new computations (size=16)
[2024-05-26 02:51:59.631] WORK  (webs.wf.moldesign.workflow) :: Submitting inference tasks
[2024-05-26 02:52:19.604] WORK  (webs.wf.moldesign.workflow) :: Inference results received (size=130258)
[2024-05-26 02:52:19.629] WORK  (webs.wf.moldesign.workflow) :: Submitted new computations (size=16)
[2024-05-26 02:52:19.719] ERROR (concurrent.futures) :: exception calling callback for <Future at 0x7f2184d88410 state=finished raised ValueError>
concurrent.futures.process._RemoteTraceback: 
"""
Traceback (most recent call last):
  File "/home/cc/miniconda3/envs/taps/lib/python3.11/concurrent/futures/process.py", line 261, in _process_worker
    r = call_item.fn(*call_item.args, **call_item.kwargs)
        ^^^^^^^^^^^^^^^^^^^^^^^^^^^^^^^^^^^^^^^^^^^^^^^^^
  File "/home/cc/taps/webs/executor/workflow.py", line 118, in __call__
    result = self.function(*args, **kwargs)
             ^^^^^^^^^^^^^^^^^^^^^^^^^^^^^^
  File "/home/cc/taps/webs/wf/moldesign/chemfunctions.py", line 118, in _compute_vertical
    xyz = generate_initial_xyz(smiles)
          ^^^^^^^^^^^^^^^^^^^^^^^^^^^^
  File "/home/cc/taps/webs/wf/moldesign/chemfunctions.py", line 72, in generate_initial_xyz
    AllChem.MMFFOptimizeMolecule(mol)
ValueError: Bad Conformer Id
"""

The above exception was the direct cause of the following exception:

Traceback (most recent call last):
  File "/home/cc/miniconda3/envs/taps/lib/python3.11/concurrent/futures/_base.py", line 340, in _invoke_callbacks
    callback(self)
  File "/home/cc/taps/webs/executor/workflow.py", line 271, in _task_done_callback
    execution_info = future.result().info
                     ^^^^^^^^^^^^^^^
  File "/home/cc/miniconda3/envs/taps/lib/python3.11/concurrent/futures/_base.py", line 449, in result
    return self.__get_result()
           ^^^^^^^^^^^^^^^^^^^
  File "/home/cc/miniconda3/envs/taps/lib/python3.11/concurrent/futures/_base.py", line 401, in __get_result
    raise self._exception
ValueError: Bad Conformer Id
[2024-05-26 02:52:20.499] WORK  (webs.wf.moldesign.workflow) :: Submitting inference tasks
[2024-05-26 02:52:40.373] WORK  (webs.wf.moldesign.workflow) :: Inference results received (size=130258)
[2024-05-26 02:52:40.410] WORK  (webs.wf.moldesign.workflow) :: Submitted new computations (size=16)
[2024-05-26 02:52:42.170] RUN   (webs.run) :: Finished workflow (name=moldesign, runtime=83.33s, tasks=346)
